[2023-03-09T13:55:16.151+0000] {taskinstance.py:1083} INFO - Dependencies all met for <TaskInstance: dag_sql.update_dados_tb_data_engineering scheduled__2023-03-09T12:30:00+00:00 [queued]>
[2023-03-09T13:55:16.347+0000] {taskinstance.py:1083} INFO - Dependencies all met for <TaskInstance: dag_sql.update_dados_tb_data_engineering scheduled__2023-03-09T12:30:00+00:00 [queued]>
[2023-03-09T13:55:16.351+0000] {taskinstance.py:1279} INFO - 
--------------------------------------------------------------------------------
[2023-03-09T13:55:16.368+0000] {taskinstance.py:1280} INFO - Starting attempt 1 of 1
[2023-03-09T13:55:16.369+0000] {taskinstance.py:1281} INFO - 
--------------------------------------------------------------------------------
[2023-03-09T13:55:16.527+0000] {taskinstance.py:1300} INFO - Executing <Task(PostgresOperator): update_dados_tb_data_engineering> on 2023-03-09 12:30:00+00:00
[2023-03-09T13:55:16.541+0000] {standard_task_runner.py:55} INFO - Started process 1296 to run task
[2023-03-09T13:55:16.590+0000] {standard_task_runner.py:82} INFO - Running: ['***', 'tasks', 'run', 'dag_sql', 'update_dados_tb_data_engineering', 'scheduled__2023-03-09T12:30:00+00:00', '--job-id', '150', '--raw', '--subdir', 'DAGS_FOLDER/dag_sql.py', '--cfg-path', '/tmp/tmp5fer9qb1']
[2023-03-09T13:55:16.617+0000] {standard_task_runner.py:83} INFO - Job 150: Subtask update_dados_tb_data_engineering
[2023-03-09T13:55:17.228+0000] {task_command.py:388} INFO - Running <TaskInstance: dag_sql.update_dados_tb_data_engineering scheduled__2023-03-09T12:30:00+00:00 [running]> on host 55fa40ce7ec1
[2023-03-09T13:55:17.684+0000] {abstractoperator.py:613} ERROR - Exception rendering Jinja template for task 'update_dados_tb_data_engineering', field 'sql'. Template: 'update_dados_tb_data_engineering.sql'
Traceback (most recent call last):
  File "/home/airflow/.local/lib/python3.7/site-packages/airflow/models/abstractoperator.py", line 606, in _do_render_template_fields
    seen_oids,
  File "/home/airflow/.local/lib/python3.7/site-packages/airflow/models/abstractoperator.py", line 657, in render_template
    template = jinja_env.get_template(value)
  File "/home/airflow/.local/lib/python3.7/site-packages/jinja2/environment.py", line 1010, in get_template
    return self._load_template(name, globals)
  File "/home/airflow/.local/lib/python3.7/site-packages/jinja2/environment.py", line 969, in _load_template
    template = self.loader.load(self, name, self.make_globals(globals))
  File "/home/airflow/.local/lib/python3.7/site-packages/jinja2/loaders.py", line 126, in load
    source, filename, uptodate = self.get_source(environment, name)
  File "/home/airflow/.local/lib/python3.7/site-packages/jinja2/loaders.py", line 218, in get_source
    raise TemplateNotFound(template)
jinja2.exceptions.TemplateNotFound: update_dados_tb_data_engineering.sql
[2023-03-09T13:55:17.690+0000] {taskinstance.py:1768} ERROR - Task failed with exception
Traceback (most recent call last):
  File "/home/airflow/.local/lib/python3.7/site-packages/airflow/models/taskinstance.py", line 1374, in _run_raw_task
    self._execute_task_with_callbacks(context, test_mode)
  File "/home/airflow/.local/lib/python3.7/site-packages/airflow/models/taskinstance.py", line 1493, in _execute_task_with_callbacks
    task_orig = self.render_templates(context=context)
  File "/home/airflow/.local/lib/python3.7/site-packages/airflow/models/taskinstance.py", line 2115, in render_templates
    original_task.render_template_fields(context)
  File "/home/airflow/.local/lib/python3.7/site-packages/airflow/models/baseoperator.py", line 1179, in render_template_fields
    self._do_render_template_fields(self, self.template_fields, context, jinja_env, set())
  File "/home/airflow/.local/lib/python3.7/site-packages/airflow/utils/session.py", line 75, in wrapper
    return func(*args, session=session, **kwargs)
  File "/home/airflow/.local/lib/python3.7/site-packages/airflow/models/abstractoperator.py", line 606, in _do_render_template_fields
    seen_oids,
  File "/home/airflow/.local/lib/python3.7/site-packages/airflow/models/abstractoperator.py", line 657, in render_template
    template = jinja_env.get_template(value)
  File "/home/airflow/.local/lib/python3.7/site-packages/jinja2/environment.py", line 1010, in get_template
    return self._load_template(name, globals)
  File "/home/airflow/.local/lib/python3.7/site-packages/jinja2/environment.py", line 969, in _load_template
    template = self.loader.load(self, name, self.make_globals(globals))
  File "/home/airflow/.local/lib/python3.7/site-packages/jinja2/loaders.py", line 126, in load
    source, filename, uptodate = self.get_source(environment, name)
  File "/home/airflow/.local/lib/python3.7/site-packages/jinja2/loaders.py", line 218, in get_source
    raise TemplateNotFound(template)
jinja2.exceptions.TemplateNotFound: update_dados_tb_data_engineering.sql
[2023-03-09T13:55:17.747+0000] {taskinstance.py:1323} INFO - Marking task as FAILED. dag_id=dag_sql, task_id=update_dados_tb_data_engineering, execution_date=20230309T123000, start_date=20230309T135516, end_date=20230309T135517
[2023-03-09T13:55:17.902+0000] {standard_task_runner.py:105} ERROR - Failed to execute job 150 for task update_dados_tb_data_engineering (update_dados_tb_data_engineering.sql; 1296)
[2023-03-09T13:55:18.086+0000] {local_task_job.py:208} INFO - Task exited with return code 1
[2023-03-09T13:55:18.186+0000] {taskinstance.py:2578} INFO - 0 downstream tasks scheduled from follow-on schedule check
