[2023-03-08T02:27:27.032+0000] {taskinstance.py:1083} INFO - Dependencies all met for <TaskInstance: teste_dag.captura_dados scheduled__2023-03-06T17:30:00+00:00 [queued]>
[2023-03-08T02:27:27.138+0000] {taskinstance.py:1083} INFO - Dependencies all met for <TaskInstance: teste_dag.captura_dados scheduled__2023-03-06T17:30:00+00:00 [queued]>
[2023-03-08T02:27:27.154+0000] {taskinstance.py:1279} INFO - 
--------------------------------------------------------------------------------
[2023-03-08T02:27:27.249+0000] {taskinstance.py:1280} INFO - Starting attempt 1 of 1
[2023-03-08T02:27:27.277+0000] {taskinstance.py:1281} INFO - 
--------------------------------------------------------------------------------
[2023-03-08T02:27:27.387+0000] {taskinstance.py:1300} INFO - Executing <Task(PythonOperator): captura_dados> on 2023-03-06 17:30:00+00:00
[2023-03-08T02:27:27.409+0000] {standard_task_runner.py:55} INFO - Started process 98 to run task
[2023-03-08T02:27:27.415+0000] {standard_task_runner.py:82} INFO - Running: ['***', 'tasks', 'run', 'teste_dag', 'captura_dados', 'scheduled__2023-03-06T17:30:00+00:00', '--job-id', '55', '--raw', '--subdir', 'DAGS_FOLDER/teste_dag.py', '--cfg-path', '/tmp/tmpfignki9n']
[2023-03-08T02:27:27.470+0000] {standard_task_runner.py:83} INFO - Job 55: Subtask captura_dados
[2023-03-08T02:27:27.873+0000] {task_command.py:388} INFO - Running <TaskInstance: teste_dag.captura_dados scheduled__2023-03-06T17:30:00+00:00 [running]> on host 7f79bdfefada
[2023-03-08T02:27:28.182+0000] {taskinstance.py:1509} INFO - Exporting the following env vars:
AIRFLOW_CTX_DAG_OWNER=***
AIRFLOW_CTX_DAG_ID=teste_dag
AIRFLOW_CTX_TASK_ID=captura_dados
AIRFLOW_CTX_EXECUTION_DATE=2023-03-06T17:30:00+00:00
AIRFLOW_CTX_TRY_NUMBER=1
AIRFLOW_CTX_DAG_RUN_ID=scheduled__2023-03-06T17:30:00+00:00
[2023-03-08T02:27:32.411+0000] {taskinstance.py:1768} ERROR - Task failed with exception
Traceback (most recent call last):
  File "/home/airflow/.local/lib/python3.7/site-packages/urllib3/connectionpool.py", line 710, in urlopen
    chunked=chunked,
  File "/home/airflow/.local/lib/python3.7/site-packages/urllib3/connectionpool.py", line 386, in _make_request
    self._validate_conn(conn)
  File "/home/airflow/.local/lib/python3.7/site-packages/urllib3/connectionpool.py", line 1042, in _validate_conn
    conn.connect()
  File "/home/airflow/.local/lib/python3.7/site-packages/urllib3/connection.py", line 424, in connect
    tls_in_tls=tls_in_tls,
  File "/home/airflow/.local/lib/python3.7/site-packages/urllib3/util/ssl_.py", line 450, in ssl_wrap_socket
    sock, context, tls_in_tls, server_hostname=server_hostname
  File "/home/airflow/.local/lib/python3.7/site-packages/urllib3/util/ssl_.py", line 493, in _ssl_wrap_socket_impl
    return ssl_context.wrap_socket(sock, server_hostname=server_hostname)
  File "/usr/local/lib/python3.7/ssl.py", line 423, in wrap_socket
    session=session
  File "/usr/local/lib/python3.7/ssl.py", line 870, in _create
    self.do_handshake()
  File "/usr/local/lib/python3.7/ssl.py", line 1139, in do_handshake
    self._sslobj.do_handshake()
ssl.SSLCertVerificationError: [SSL: CERTIFICATE_VERIFY_FAILED] certificate verify failed: self signed certificate in certificate chain (_ssl.c:1091)

During handling of the above exception, another exception occurred:

Traceback (most recent call last):
  File "/home/airflow/.local/lib/python3.7/site-packages/requests/adapters.py", line 499, in send
    timeout=timeout,
  File "/home/airflow/.local/lib/python3.7/site-packages/urllib3/connectionpool.py", line 788, in urlopen
    method, url, error=e, _pool=self, _stacktrace=sys.exc_info()[2]
  File "/home/airflow/.local/lib/python3.7/site-packages/urllib3/util/retry.py", line 592, in increment
    raise MaxRetryError(_pool, url, error or ResponseError(cause))
urllib3.exceptions.MaxRetryError: HTTPSConnectionPool(host='data.cityofnewyork.us', port=443): Max retries exceeded with url: /resource/rc75-m7u3.json (Caused by SSLError(SSLCertVerificationError(1, '[SSL: CERTIFICATE_VERIFY_FAILED] certificate verify failed: self signed certificate in certificate chain (_ssl.c:1091)')))

During handling of the above exception, another exception occurred:

Traceback (most recent call last):
  File "/home/airflow/.local/lib/python3.7/site-packages/airflow/operators/python.py", line 175, in execute
    return_value = self.execute_callable()
  File "/home/airflow/.local/lib/python3.7/site-packages/airflow/operators/python.py", line 192, in execute_callable
    return self.python_callable(*self.op_args, **self.op_kwargs)
  File "/opt/airflow/dags/teste_dag.py", line 11, in captura_conta_dados
    response = requests.get(url)
  File "/home/airflow/.local/lib/python3.7/site-packages/requests/api.py", line 73, in get
    return request("get", url, params=params, **kwargs)
  File "/home/airflow/.local/lib/python3.7/site-packages/requests/api.py", line 59, in request
    return session.request(method=method, url=url, **kwargs)
  File "/home/airflow/.local/lib/python3.7/site-packages/requests/sessions.py", line 587, in request
    resp = self.send(prep, **send_kwargs)
  File "/home/airflow/.local/lib/python3.7/site-packages/requests/sessions.py", line 701, in send
    r = adapter.send(request, **kwargs)
  File "/home/airflow/.local/lib/python3.7/site-packages/requests/adapters.py", line 563, in send
    raise SSLError(e, request=request)
requests.exceptions.SSLError: HTTPSConnectionPool(host='data.cityofnewyork.us', port=443): Max retries exceeded with url: /resource/rc75-m7u3.json (Caused by SSLError(SSLCertVerificationError(1, '[SSL: CERTIFICATE_VERIFY_FAILED] certificate verify failed: self signed certificate in certificate chain (_ssl.c:1091)')))
[2023-03-08T02:27:32.796+0000] {taskinstance.py:1323} INFO - Marking task as FAILED. dag_id=teste_dag, task_id=captura_dados, execution_date=20230306T173000, start_date=20230308T022727, end_date=20230308T022732
[2023-03-08T02:27:32.858+0000] {standard_task_runner.py:105} ERROR - Failed to execute job 55 for task captura_dados (HTTPSConnectionPool(host='data.cityofnewyork.us', port=443): Max retries exceeded with url: /resource/rc75-m7u3.json (Caused by SSLError(SSLCertVerificationError(1, '[SSL: CERTIFICATE_VERIFY_FAILED] certificate verify failed: self signed certificate in certificate chain (_ssl.c:1091)'))); 98)
[2023-03-08T02:27:32.909+0000] {local_task_job.py:208} INFO - Task exited with return code 1
[2023-03-08T02:27:32.997+0000] {taskinstance.py:2578} INFO - 0 downstream tasks scheduled from follow-on schedule check
