[2023-05-01T01:07:45.798+0000] {taskinstance.py:1083} INFO - Dependencies all met for <TaskInstance: create_infra.create_table scheduled__2023-04-30T00:00:00+00:00 [queued]>
[2023-05-01T01:07:45.817+0000] {taskinstance.py:1083} INFO - Dependencies all met for <TaskInstance: create_infra.create_table scheduled__2023-04-30T00:00:00+00:00 [queued]>
[2023-05-01T01:07:45.818+0000] {taskinstance.py:1279} INFO - 
--------------------------------------------------------------------------------
[2023-05-01T01:07:45.822+0000] {taskinstance.py:1280} INFO - Starting attempt 1 of 2
[2023-05-01T01:07:45.822+0000] {taskinstance.py:1281} INFO - 
--------------------------------------------------------------------------------
[2023-05-01T01:07:45.842+0000] {taskinstance.py:1300} INFO - Executing <Task(BigQueryCreateEmptyTableOperator): create_table> on 2023-04-30 00:00:00+00:00
[2023-05-01T01:07:45.851+0000] {standard_task_runner.py:55} INFO - Started process 24447 to run task
[2023-05-01T01:07:45.856+0000] {standard_task_runner.py:82} INFO - Running: ['***', 'tasks', 'run', 'create_infra', 'create_table', 'scheduled__2023-04-30T00:00:00+00:00', '--job-id', '493', '--raw', '--subdir', 'DAGS_FOLDER/create_infra.py', '--cfg-path', '/tmp/tmpooct4i_s']
[2023-05-01T01:07:45.860+0000] {standard_task_runner.py:83} INFO - Job 493: Subtask create_table
[2023-05-01T01:07:45.965+0000] {task_command.py:388} INFO - Running <TaskInstance: create_infra.create_table scheduled__2023-04-30T00:00:00+00:00 [running]> on host 32f6cac2461e
[2023-05-01T01:07:46.065+0000] {taskinstance.py:1509} INFO - Exporting the following env vars:
AIRFLOW_CTX_DAG_OWNER=Junior Lafuente
AIRFLOW_CTX_DAG_ID=create_infra
AIRFLOW_CTX_TASK_ID=create_table
AIRFLOW_CTX_EXECUTION_DATE=2023-04-30T00:00:00+00:00
AIRFLOW_CTX_TRY_NUMBER=1
AIRFLOW_CTX_DAG_RUN_ID=scheduled__2023-04-30T00:00:00+00:00
[2023-05-01T01:07:46.087+0000] {taskinstance.py:1768} ERROR - Task failed with exception
Traceback (most recent call last):
  File "/home/airflow/.local/lib/python3.7/site-packages/airflow/providers/google/cloud/operators/bigquery.py", line 1327, in execute
    impersonation_chain=self.impersonation_chain,
  File "/home/airflow/.local/lib/python3.7/site-packages/airflow/providers/google/cloud/hooks/bigquery.py", line 103, in __init__
    impersonation_chain=impersonation_chain,
  File "/home/airflow/.local/lib/python3.7/site-packages/airflow/providers/google/common/hooks/base_google.py", line 231, in __init__
    self.extras: dict = self.get_connection(self.gcp_conn_id).extra_dejson
  File "/home/airflow/.local/lib/python3.7/site-packages/airflow/hooks/base.py", line 72, in get_connection
    conn = Connection.get_connection_from_secrets(conn_id)
  File "/home/airflow/.local/lib/python3.7/site-packages/airflow/models/connection.py", line 435, in get_connection_from_secrets
    raise AirflowNotFoundException(f"The conn_id `{conn_id}` isn't defined")
airflow.exceptions.AirflowNotFoundException: The conn_id `google_cloud_default` isn't defined
[2023-05-01T01:07:46.094+0000] {taskinstance.py:1323} INFO - Marking task as UP_FOR_RETRY. dag_id=create_infra, task_id=create_table, execution_date=20230430T000000, start_date=20230501T010745, end_date=20230501T010746
[2023-05-01T01:07:46.107+0000] {standard_task_runner.py:105} ERROR - Failed to execute job 493 for task create_table (The conn_id `google_cloud_default` isn't defined; 24447)
[2023-05-01T01:07:46.134+0000] {local_task_job.py:208} INFO - Task exited with return code 1
[2023-05-01T01:07:46.160+0000] {taskinstance.py:2578} INFO - 0 downstream tasks scheduled from follow-on schedule check
