[2023-03-05T00:07:08.559+0000] {taskinstance.py:1083} INFO - Dependencies all met for <TaskInstance: teste_dag.evalido scheduled__2023-03-04T22:30:00+00:00 [queued]>
[2023-03-05T00:07:08.576+0000] {taskinstance.py:1083} INFO - Dependencies all met for <TaskInstance: teste_dag.evalido scheduled__2023-03-04T22:30:00+00:00 [queued]>
[2023-03-05T00:07:08.577+0000] {taskinstance.py:1279} INFO - 
--------------------------------------------------------------------------------
[2023-03-05T00:07:08.577+0000] {taskinstance.py:1280} INFO - Starting attempt 1 of 1
[2023-03-05T00:07:08.579+0000] {taskinstance.py:1281} INFO - 
--------------------------------------------------------------------------------
[2023-03-05T00:07:08.600+0000] {taskinstance.py:1300} INFO - Executing <Task(PythonOperator): evalido> on 2023-03-04 22:30:00+00:00
[2023-03-05T00:07:08.607+0000] {standard_task_runner.py:55} INFO - Started process 4468 to run task
[2023-03-05T00:07:08.611+0000] {standard_task_runner.py:82} INFO - Running: ['***', 'tasks', 'run', 'teste_dag', 'evalido', 'scheduled__2023-03-04T22:30:00+00:00', '--job-id', '4', '--raw', '--subdir', 'DAGS_FOLDER/teste_dag.py', '--cfg-path', '/tmp/tmpjlvzyzbq']
[2023-03-05T00:07:08.612+0000] {standard_task_runner.py:83} INFO - Job 4: Subtask evalido
[2023-03-05T00:07:08.706+0000] {task_command.py:388} INFO - Running <TaskInstance: teste_dag.evalido scheduled__2023-03-04T22:30:00+00:00 [running]> on host 3d4e7c789958
[2023-03-05T00:07:08.912+0000] {taskinstance.py:1509} INFO - Exporting the following env vars:
AIRFLOW_CTX_DAG_OWNER=***
AIRFLOW_CTX_DAG_ID=teste_dag
AIRFLOW_CTX_TASK_ID=evalido
AIRFLOW_CTX_EXECUTION_DATE=2023-03-04T22:30:00+00:00
AIRFLOW_CTX_TRY_NUMBER=1
AIRFLOW_CTX_DAG_RUN_ID=scheduled__2023-03-04T22:30:00+00:00
[2023-03-05T00:07:08.942+0000] {taskinstance.py:1768} ERROR - Task failed with exception
Traceback (most recent call last):
  File "/home/airflow/.local/lib/python3.7/site-packages/airflow/operators/python.py", line 175, in execute
    return_value = self.execute_callable()
  File "/home/airflow/.local/lib/python3.7/site-packages/airflow/operators/python.py", line 192, in execute_callable
    return self.python_callable(*self.op_args, **self.op_kwargs)
  File "/opt/airflow/dags/teste_dag.py", line 18, in evalido
    if (qtd > 1000):
TypeError: '>' not supported between instances of 'NoneType' and 'int'
[2023-03-05T00:07:09.035+0000] {taskinstance.py:1323} INFO - Marking task as FAILED. dag_id=teste_dag, task_id=evalido, execution_date=20230304T223000, start_date=20230305T000708, end_date=20230305T000709
[2023-03-05T00:07:09.073+0000] {standard_task_runner.py:105} ERROR - Failed to execute job 4 for task evalido ('>' not supported between instances of 'NoneType' and 'int'; 4468)
[2023-03-05T00:07:09.126+0000] {local_task_job.py:208} INFO - Task exited with return code 1
[2023-03-05T00:07:09.225+0000] {taskinstance.py:2578} INFO - 0 downstream tasks scheduled from follow-on schedule check
