[2023-05-03T02:13:56.817+0000] {taskinstance.py:1083} INFO - Dependencies all met for <TaskInstance: gsc_to_bq.gcs_sensor scheduled__2023-04-30T00:00:00+00:00 [queued]>
[2023-05-03T02:13:56.894+0000] {taskinstance.py:1083} INFO - Dependencies all met for <TaskInstance: gsc_to_bq.gcs_sensor scheduled__2023-04-30T00:00:00+00:00 [queued]>
[2023-05-03T02:13:56.895+0000] {taskinstance.py:1279} INFO - 
--------------------------------------------------------------------------------
[2023-05-03T02:13:56.897+0000] {taskinstance.py:1280} INFO - Starting attempt 2 of 3
[2023-05-03T02:13:56.897+0000] {taskinstance.py:1281} INFO - 
--------------------------------------------------------------------------------
[2023-05-03T02:13:56.979+0000] {taskinstance.py:1300} INFO - Executing <Task(GCSObjectExistenceSensor): gcs_sensor> on 2023-04-30 00:00:00+00:00
[2023-05-03T02:13:56.996+0000] {standard_task_runner.py:55} INFO - Started process 13154 to run task
[2023-05-03T02:13:57.016+0000] {standard_task_runner.py:82} INFO - Running: ['***', 'tasks', 'run', 'gsc_to_bq', 'gcs_sensor', 'scheduled__2023-04-30T00:00:00+00:00', '--job-id', '596', '--raw', '--subdir', 'DAGS_FOLDER/gcs_to_bq.py', '--cfg-path', '/tmp/tmp1l_pdgj9']
[2023-05-03T02:13:57.035+0000] {standard_task_runner.py:83} INFO - Job 596: Subtask gcs_sensor
[2023-05-03T02:13:57.519+0000] {task_command.py:388} INFO - Running <TaskInstance: gsc_to_bq.gcs_sensor scheduled__2023-04-30T00:00:00+00:00 [running]> on host da959356c36a
[2023-05-03T02:13:58.486+0000] {taskinstance.py:1509} INFO - Exporting the following env vars:
AIRFLOW_CTX_DAG_OWNER=Junior Lafuente
AIRFLOW_CTX_DAG_ID=gsc_to_bq
AIRFLOW_CTX_TASK_ID=gcs_sensor
AIRFLOW_CTX_EXECUTION_DATE=2023-04-30T00:00:00+00:00
AIRFLOW_CTX_TRY_NUMBER=2
AIRFLOW_CTX_DAG_RUN_ID=scheduled__2023-04-30T00:00:00+00:00
[2023-05-03T02:13:58.607+0000] {gcs.py:89} INFO - Sensor checks existence of : bucket_raw_jr, function/main.zip
[2023-05-03T02:13:58.697+0000] {taskinstance.py:1768} ERROR - Task failed with exception
Traceback (most recent call last):
  File "/home/airflow/.local/lib/python3.7/site-packages/airflow/sensors/base.py", line 199, in execute
    poke_return = self.poke(context)
  File "/home/airflow/.local/lib/python3.7/site-packages/airflow/providers/google/cloud/sensors/gcs.py", line 93, in poke
    impersonation_chain=self.impersonation_chain,
  File "/home/airflow/.local/lib/python3.7/site-packages/airflow/providers/google/cloud/hooks/gcs.py", line 150, in __init__
    impersonation_chain=impersonation_chain,
  File "/home/airflow/.local/lib/python3.7/site-packages/airflow/providers/google/common/hooks/base_google.py", line 231, in __init__
    self.extras: dict = self.get_connection(self.gcp_conn_id).extra_dejson
  File "/home/airflow/.local/lib/python3.7/site-packages/airflow/hooks/base.py", line 72, in get_connection
    conn = Connection.get_connection_from_secrets(conn_id)
  File "/home/airflow/.local/lib/python3.7/site-packages/airflow/models/connection.py", line 435, in get_connection_from_secrets
    raise AirflowNotFoundException(f"The conn_id `{conn_id}` isn't defined")
airflow.exceptions.AirflowNotFoundException: The conn_id `google_cloud_default` isn't defined
[2023-05-03T02:13:58.735+0000] {taskinstance.py:1323} INFO - Marking task as UP_FOR_RETRY. dag_id=gsc_to_bq, task_id=gcs_sensor, execution_date=20230430T000000, start_date=20230503T021356, end_date=20230503T021358
[2023-05-03T02:13:58.818+0000] {standard_task_runner.py:105} ERROR - Failed to execute job 596 for task gcs_sensor (The conn_id `google_cloud_default` isn't defined; 13154)
[2023-05-03T02:13:58.879+0000] {local_task_job.py:208} INFO - Task exited with return code 1
[2023-05-03T02:13:59.016+0000] {taskinstance.py:2578} INFO - 0 downstream tasks scheduled from follow-on schedule check
