[2023-04-28T18:24:48.378+0000] {taskinstance.py:1083} INFO - Dependencies all met for <TaskInstance: gsc_to_bq.create_bucket_raw scheduled__2023-04-27T00:00:00+00:00 [queued]>
[2023-04-28T18:24:48.404+0000] {taskinstance.py:1083} INFO - Dependencies all met for <TaskInstance: gsc_to_bq.create_bucket_raw scheduled__2023-04-27T00:00:00+00:00 [queued]>
[2023-04-28T18:24:48.405+0000] {taskinstance.py:1279} INFO - 
--------------------------------------------------------------------------------
[2023-04-28T18:24:48.406+0000] {taskinstance.py:1280} INFO - Starting attempt 6 of 7
[2023-04-28T18:24:48.406+0000] {taskinstance.py:1281} INFO - 
--------------------------------------------------------------------------------
[2023-04-28T18:24:48.438+0000] {taskinstance.py:1300} INFO - Executing <Task(GCSCreateBucketOperator): create_bucket_raw> on 2023-04-27 00:00:00+00:00
[2023-04-28T18:24:48.451+0000] {standard_task_runner.py:55} INFO - Started process 218 to run task
[2023-04-28T18:24:48.456+0000] {standard_task_runner.py:82} INFO - Running: ['***', 'tasks', 'run', 'gsc_to_bq', 'create_bucket_raw', 'scheduled__2023-04-27T00:00:00+00:00', '--job-id', '443', '--raw', '--subdir', 'DAGS_FOLDER/gcs_to_bq.py', '--cfg-path', '/tmp/tmpif8quqpd']
[2023-04-28T18:24:48.460+0000] {standard_task_runner.py:83} INFO - Job 443: Subtask create_bucket_raw
[2023-04-28T18:24:48.585+0000] {task_command.py:388} INFO - Running <TaskInstance: gsc_to_bq.create_bucket_raw scheduled__2023-04-27T00:00:00+00:00 [running]> on host e78efd09126d
[2023-04-28T18:24:48.721+0000] {taskinstance.py:1509} INFO - Exporting the following env vars:
AIRFLOW_CTX_DAG_OWNER=Junior Lafuente
AIRFLOW_CTX_DAG_ID=gsc_to_bq
AIRFLOW_CTX_TASK_ID=create_bucket_raw
AIRFLOW_CTX_EXECUTION_DATE=2023-04-27T00:00:00+00:00
AIRFLOW_CTX_TRY_NUMBER=6
AIRFLOW_CTX_DAG_RUN_ID=scheduled__2023-04-27T00:00:00+00:00
[2023-04-28T18:24:48.754+0000] {base.py:73} INFO - Using connection ID 'gcp' for task execution.
[2023-04-28T18:24:48.803+0000] {gcs.py:880} INFO - Creating Bucket: bucket_raw_jr; Location: us-central1; Storage Class: STANDARD
[2023-04-28T18:28:22.973+0000] {local_task_job.py:273} WARNING - State of this instance has been externally set to restarting. Terminating instance.
[2023-04-28T18:28:22.980+0000] {process_utils.py:133} INFO - Sending Signals.SIGTERM to group 218. PIDs of all processes in the group: [218]
[2023-04-28T18:28:22.981+0000] {process_utils.py:84} INFO - Sending the signal Signals.SIGTERM to group 218
[2023-04-28T18:28:22.983+0000] {taskinstance.py:1479} ERROR - Received SIGTERM. Terminating subprocesses.
[2023-04-28T18:28:23.009+0000] {taskinstance.py:1768} ERROR - Task failed with exception
Traceback (most recent call last):
  File "/home/airflow/.local/lib/python3.7/site-packages/airflow/providers/google/cloud/operators/gcs.py", line 158, in execute
    labels=self.labels,
  File "/home/airflow/.local/lib/python3.7/site-packages/airflow/providers/google/common/hooks/base_google.py", line 462, in inner_wrapper
    return func(self, *args, **kwargs)
  File "/home/airflow/.local/lib/python3.7/site-packages/airflow/providers/google/cloud/hooks/gcs.py", line 897, in create_bucket
    bucket.create(project=project_id, location=location)
  File "/home/airflow/.local/lib/python3.7/site-packages/google/cloud/storage/bucket.py", line 989, in create
    retry=retry,
  File "/home/airflow/.local/lib/python3.7/site-packages/google/cloud/storage/client.py", line 954, in create_bucket
    _target_object=bucket,
  File "/home/airflow/.local/lib/python3.7/site-packages/google/cloud/storage/client.py", line 620, in _post_resource
    _target_object=_target_object,
  File "/home/airflow/.local/lib/python3.7/site-packages/google/cloud/storage/_http.py", line 72, in api_request
    return call()
  File "/home/airflow/.local/lib/python3.7/site-packages/google/api_core/retry.py", line 288, in retry_wrapped_func
    on_error=on_error,
  File "/home/airflow/.local/lib/python3.7/site-packages/google/api_core/retry.py", line 190, in retry_target
    return target()
  File "/home/airflow/.local/lib/python3.7/site-packages/google/cloud/_http/__init__.py", line 490, in api_request
    extra_api_info=extra_api_info,
  File "/home/airflow/.local/lib/python3.7/site-packages/google/cloud/_http/__init__.py", line 342, in _make_request
    method, url, headers, data, target_object, timeout=timeout
  File "/home/airflow/.local/lib/python3.7/site-packages/google/cloud/_http/__init__.py", line 380, in _do_request
    url=url, method=method, headers=headers, data=data, timeout=timeout
  File "/home/airflow/.local/lib/python3.7/site-packages/google/auth/transport/requests.py", line 545, in request
    self.credentials.before_request(auth_request, method, url, request_headers)
  File "/home/airflow/.local/lib/python3.7/site-packages/google/auth/credentials.py", line 135, in before_request
    self.refresh(request)
  File "/home/airflow/.local/lib/python3.7/site-packages/google/oauth2/service_account.py", line 430, in refresh
    request, self._token_uri, assertion
  File "/home/airflow/.local/lib/python3.7/site-packages/google/oauth2/_client.py", line 295, in jwt_grant
    request, token_uri, body, can_retry=can_retry
  File "/home/airflow/.local/lib/python3.7/site-packages/google/oauth2/_client.py", line 262, in _token_endpoint_request
    **kwargs
  File "/home/airflow/.local/lib/python3.7/site-packages/google/oauth2/_client.py", line 204, in _token_endpoint_request_no_throw
    request_succeeded, response_data, retryable_error = _perform_request()
  File "/home/airflow/.local/lib/python3.7/site-packages/google/oauth2/_client.py", line 181, in _perform_request
    method="POST", url=token_uri, headers=headers, body=body, **kwargs
  File "/home/airflow/.local/lib/python3.7/site-packages/google/auth/transport/requests.py", line 194, in __call__
    method, url, data=body, headers=headers, timeout=timeout, **kwargs
  File "/home/airflow/.local/lib/python3.7/site-packages/requests/sessions.py", line 587, in request
    resp = self.send(prep, **send_kwargs)
  File "/home/airflow/.local/lib/python3.7/site-packages/requests/sessions.py", line 701, in send
    r = adapter.send(request, **kwargs)
  File "/home/airflow/.local/lib/python3.7/site-packages/requests/adapters.py", line 499, in send
    timeout=timeout,
  File "/home/airflow/.local/lib/python3.7/site-packages/urllib3/connectionpool.py", line 710, in urlopen
    chunked=chunked,
  File "/home/airflow/.local/lib/python3.7/site-packages/urllib3/connectionpool.py", line 386, in _make_request
    self._validate_conn(conn)
  File "/home/airflow/.local/lib/python3.7/site-packages/urllib3/connectionpool.py", line 1042, in _validate_conn
    conn.connect()
  File "/home/airflow/.local/lib/python3.7/site-packages/urllib3/connection.py", line 358, in connect
    self.sock = conn = self._new_conn()
  File "/home/airflow/.local/lib/python3.7/site-packages/urllib3/connection.py", line 175, in _new_conn
    (self._dns_host, self.port), self.timeout, **extra_kw
  File "/home/airflow/.local/lib/python3.7/site-packages/urllib3/util/connection.py", line 85, in create_connection
    sock.connect(sa)
  File "/home/airflow/.local/lib/python3.7/site-packages/airflow/models/taskinstance.py", line 1481, in signal_handler
    raise AirflowException("Task received SIGTERM signal")
airflow.exceptions.AirflowException: Task received SIGTERM signal
[2023-04-28T18:28:23.025+0000] {taskinstance.py:1323} INFO - Marking task as UP_FOR_RETRY. dag_id=gsc_to_bq, task_id=create_bucket_raw, execution_date=20230427T000000, start_date=20230428T182448, end_date=20230428T182823
[2023-04-28T18:28:23.057+0000] {standard_task_runner.py:105} ERROR - Failed to execute job 443 for task create_bucket_raw (Task received SIGTERM signal; 218)
[2023-04-28T18:28:23.099+0000] {process_utils.py:79} INFO - Process psutil.Process(pid=218, status='terminated', exitcode=1, started='18:24:47') (218) terminated with exit code 1
