[2023-05-03T23:21:32.906+0000] {taskinstance.py:1083} INFO - Dependencies all met for <TaskInstance: gsc_to_bq.ingest_dado scheduled__2023-05-02T00:00:00+00:00 [queued]>
[2023-05-03T23:21:32.926+0000] {taskinstance.py:1083} INFO - Dependencies all met for <TaskInstance: gsc_to_bq.ingest_dado scheduled__2023-05-02T00:00:00+00:00 [queued]>
[2023-05-03T23:21:32.927+0000] {taskinstance.py:1279} INFO - 
--------------------------------------------------------------------------------
[2023-05-03T23:21:32.928+0000] {taskinstance.py:1280} INFO - Starting attempt 73 of 74
[2023-05-03T23:21:32.929+0000] {taskinstance.py:1281} INFO - 
--------------------------------------------------------------------------------
[2023-05-03T23:21:32.960+0000] {taskinstance.py:1300} INFO - Executing <Task(PythonOperator): ingest_dado> on 2023-05-02 00:00:00+00:00
[2023-05-03T23:21:32.974+0000] {standard_task_runner.py:55} INFO - Started process 4903 to run task
[2023-05-03T23:21:32.978+0000] {standard_task_runner.py:82} INFO - Running: ['***', 'tasks', 'run', 'gsc_to_bq', 'ingest_dado', 'scheduled__2023-05-02T00:00:00+00:00', '--job-id', '712', '--raw', '--subdir', 'DAGS_FOLDER/gcs_to_bq.py', '--cfg-path', '/tmp/tmpm2q5ivqj']
[2023-05-03T23:21:32.982+0000] {standard_task_runner.py:83} INFO - Job 712: Subtask ingest_dado
[2023-05-03T23:21:33.097+0000] {task_command.py:388} INFO - Running <TaskInstance: gsc_to_bq.ingest_dado scheduled__2023-05-02T00:00:00+00:00 [running]> on host 23a1495f3fb6
[2023-05-03T23:21:33.198+0000] {taskinstance.py:1509} INFO - Exporting the following env vars:
AIRFLOW_CTX_DAG_OWNER=Junior Lafuente
AIRFLOW_CTX_DAG_ID=gsc_to_bq
AIRFLOW_CTX_TASK_ID=ingest_dado
AIRFLOW_CTX_EXECUTION_DATE=2023-05-02T00:00:00+00:00
AIRFLOW_CTX_TRY_NUMBER=73
AIRFLOW_CTX_DAG_RUN_ID=scheduled__2023-05-02T00:00:00+00:00
[2023-05-03T23:21:34.178+0000] {logging_mixin.py:137} INFO - valor da minha KEY: /opt/***/arq/gcsToBq.json
[2023-05-03T23:21:34.253+0000] {logging_mixin.py:137} INFO - valor da minha CREDENTIALS: <google.oauth2.service_account.Credentials object at 0x7f0c0b756dd0>
[2023-05-03T23:21:34.262+0000] {_metadata.py:104} WARNING - Compute Engine Metadata server unavailable on attempt 1 of 3. Reason: Remote end closed connection without response
[2023-05-03T23:21:34.271+0000] {_metadata.py:104} WARNING - Compute Engine Metadata server unavailable on attempt 2 of 3. Reason: Remote end closed connection without response
[2023-05-03T23:21:34.276+0000] {_metadata.py:104} WARNING - Compute Engine Metadata server unavailable on attempt 3 of 3. Reason: Remote end closed connection without response
[2023-05-03T23:21:34.277+0000] {_default.py:302} WARNING - Authentication failed using Compute Engine authentication due to unavailable metadata server.
[2023-05-03T23:21:34.278+0000] {taskinstance.py:1768} ERROR - Task failed with exception
Traceback (most recent call last):
  File "/home/airflow/.local/lib/python3.7/site-packages/airflow/operators/python.py", line 175, in execute
    return_value = self.execute_callable()
  File "/home/airflow/.local/lib/python3.7/site-packages/airflow/operators/python.py", line 192, in execute_callable
    return self.python_callable(*self.op_args, **self.op_kwargs)
  File "/opt/airflow/dags/gcs_to_bq.py", line 39, in ingest_dados
    client = bigquery.Client()
  File "/home/airflow/.local/lib/python3.7/site-packages/google/cloud/bigquery/client.py", line 235, in __init__
    _http=_http,
  File "/home/airflow/.local/lib/python3.7/site-packages/google/cloud/client/__init__.py", line 320, in __init__
    _ClientProjectMixin.__init__(self, project=project, credentials=credentials)
  File "/home/airflow/.local/lib/python3.7/site-packages/google/cloud/client/__init__.py", line 268, in __init__
    project = self._determine_default(project)
  File "/home/airflow/.local/lib/python3.7/site-packages/google/cloud/client/__init__.py", line 287, in _determine_default
    return _determine_default_project(project)
  File "/home/airflow/.local/lib/python3.7/site-packages/google/cloud/_helpers/__init__.py", line 152, in _determine_default_project
    _, project = google.auth.default()
  File "/home/airflow/.local/lib/python3.7/site-packages/google/auth/_default.py", line 653, in default
    raise exceptions.DefaultCredentialsError(_HELP_MESSAGE)
google.auth.exceptions.DefaultCredentialsError: Could not automatically determine credentials. Please set GOOGLE_APPLICATION_CREDENTIALS or explicitly create credentials and re-run the application. For more information, please see https://cloud.google.com/docs/authentication/getting-started
[2023-05-03T23:21:34.300+0000] {taskinstance.py:1323} INFO - Marking task as UP_FOR_RETRY. dag_id=gsc_to_bq, task_id=ingest_dado, execution_date=20230502T000000, start_date=20230503T232132, end_date=20230503T232134
[2023-05-03T23:21:34.318+0000] {standard_task_runner.py:105} ERROR - Failed to execute job 712 for task ingest_dado (Could not automatically determine credentials. Please set GOOGLE_APPLICATION_CREDENTIALS or explicitly create credentials and re-run the application. For more information, please see https://cloud.google.com/docs/authentication/getting-started; 4903)
[2023-05-03T23:21:34.357+0000] {local_task_job.py:208} INFO - Task exited with return code 1
[2023-05-03T23:21:34.396+0000] {taskinstance.py:2578} INFO - 0 downstream tasks scheduled from follow-on schedule check
